INFO:     127.0.0.1:50132 - "GET /api/pedidos/local/5 HTTP/1.1" 500 Internal Server Error
ERROR:    Exception in ASGI application
Traceback (most recent call last):
  File "/home/poncho/Documents/Workspace/foodplaza-fastApi/.venv/lib/python3.12/site-packages/sqlalchemy/engine/base.py", line 145, in __init__
    self._dbapi_connection = engine.raw_connection()
                             ^^^^^^^^^^^^^^^^^^^^^^^
  File "/home/poncho/Documents/Workspace/foodplaza-fastApi/.venv/lib/python3.12/site-packages/sqlalchemy/engine/base.py", line 3292, in raw_connection
    return self.pool.connect()
           ^^^^^^^^^^^^^^^^^^^
  File "/home/poncho/Documents/Workspace/foodplaza-fastApi/.venv/lib/python3.12/site-packages/sqlalchemy/pool/base.py", line 452, in connect
    return _ConnectionFairy._checkout(self)
           ^^^^^^^^^^^^^^^^^^^^^^^^^^^^^^^^
  File "/home/poncho/Documents/Workspace/foodplaza-fastApi/.venv/lib/python3.12/site-packages/sqlalchemy/pool/base.py", line 1269, in _checkout
    fairy = _ConnectionRecord.checkout(pool)
            ^^^^^^^^^^^^^^^^^^^^^^^^^^^^^^^^
  File "/home/poncho/Documents/Workspace/foodplaza-fastApi/.venv/lib/python3.12/site-packages/sqlalchemy/pool/base.py", line 716, in checkout
    rec = pool._do_get()
          ^^^^^^^^^^^^^^
  File "/home/poncho/Documents/Workspace/foodplaza-fastApi/.venv/lib/python3.12/site-packages/sqlalchemy/pool/impl.py", line 169, in _do_get
    with util.safe_reraise():
  File "/home/poncho/Documents/Workspace/foodplaza-fastApi/.venv/lib/python3.12/site-packages/sqlalchemy/util/langhelpers.py", line 146, in __exit__
    raise exc_value.with_traceback(exc_tb)
  File "/home/poncho/Documents/Workspace/foodplaza-fastApi/.venv/lib/python3.12/site-packages/sqlalchemy/pool/impl.py", line 167, in _do_get
    return self._create_connection()
           ^^^^^^^^^^^^^^^^^^^^^^^^^
  File "/home/poncho/Documents/Workspace/foodplaza-fastApi/.venv/lib/python3.12/site-packages/sqlalchemy/pool/base.py", line 393, in _create_connection
    return _ConnectionRecord(self)
           ^^^^^^^^^^^^^^^^^^^^^^^
  File "/home/poncho/Documents/Workspace/foodplaza-fastApi/.venv/lib/python3.12/site-packages/sqlalchemy/pool/base.py", line 678, in __init__
    self.__connect()
  File "/home/poncho/Documents/Workspace/foodplaza-fastApi/.venv/lib/python3.12/site-packages/sqlalchemy/pool/base.py", line 902, in __connect
    with util.safe_reraise():
  File "/home/poncho/Documents/Workspace/foodplaza-fastApi/.venv/lib/python3.12/site-packages/sqlalchemy/util/langhelpers.py", line 146, in __exit__
    raise exc_value.with_traceback(exc_tb)
  File "/home/poncho/Documents/Workspace/foodplaza-fastApi/.venv/lib/python3.12/site-packages/sqlalchemy/pool/base.py", line 898, in __connect
    self.dbapi_connection = connection = pool._invoke_creator(self)
                                         ^^^^^^^^^^^^^^^^^^^^^^^^^^
  File "/home/poncho/Documents/Workspace/foodplaza-fastApi/.venv/lib/python3.12/site-packages/sqlalchemy/engine/create.py", line 637, in connect
    return dialect.connect(*cargs, **cparams)
           ^^^^^^^^^^^^^^^^^^^^^^^^^^^^^^^^^^
  File "/home/poncho/Documents/Workspace/foodplaza-fastApi/.venv/lib/python3.12/site-packages/sqlalchemy/engine/default.py", line 616, in connect
    return self.loaded_dbapi.connect(*cargs, **cparams)
           ^^^^^^^^^^^^^^^^^^^^^^^^^^^^^^^^^^^^^^^^^^^^
  File "/home/poncho/Documents/Workspace/foodplaza-fastApi/.venv/lib/python3.12/site-packages/pymysql/connections.py", line 358, in __init__
    self.connect()
  File "/home/poncho/Documents/Workspace/foodplaza-fastApi/.venv/lib/python3.12/site-packages/pymysql/connections.py", line 664, in connect
    self._request_authentication()
  File "/home/poncho/Documents/Workspace/foodplaza-fastApi/.venv/lib/python3.12/site-packages/pymysql/connections.py", line 976, in _request_authentication
    auth_packet = _auth.caching_sha2_password_auth(self, auth_packet)
                  ^^^^^^^^^^^^^^^^^^^^^^^^^^^^^^^^^^^^^^^^^^^^^^^^^^^
  File "/home/poncho/Documents/Workspace/foodplaza-fastApi/.venv/lib/python3.12/site-packages/pymysql/_auth.py", line 267, in caching_sha2_password_auth
    pkt = _roundtrip(conn, data)
          ^^^^^^^^^^^^^^^^^^^^^^
  File "/home/poncho/Documents/Workspace/foodplaza-fastApi/.venv/lib/python3.12/site-packages/pymysql/_auth.py", line 120, in _roundtrip
    pkt = conn._read_packet()
          ^^^^^^^^^^^^^^^^^^^
  File "/home/poncho/Documents/Workspace/foodplaza-fastApi/.venv/lib/python3.12/site-packages/pymysql/connections.py", line 772, in _read_packet
    packet.raise_for_error()
  File "/home/poncho/Documents/Workspace/foodplaza-fastApi/.venv/lib/python3.12/site-packages/pymysql/protocol.py", line 221, in raise_for_error
    err.raise_mysql_exception(self._data)
  File "/home/poncho/Documents/Workspace/foodplaza-fastApi/.venv/lib/python3.12/site-packages/pymysql/err.py", line 143, in raise_mysql_exception
    raise errorclass(errno, errval)
pymysql.err.OperationalError: (1045, "Access denied for user 'root'@'localhost' (using password: YES)")

The above exception was the direct cause of the following exception:

Traceback (most recent call last):
  File "/home/poncho/Documents/Workspace/foodplaza-fastApi/.venv/lib/python3.12/site-packages/uvicorn/protocols/http/httptools_impl.py", line 419, in run_asgi
    result = await app(  # type: ignore[func-returns-value]
             ^^^^^^^^^^^^^^^^^^^^^^^^^^^^^^^^^^^^^^^^^^^^^^
  File "/home/poncho/Documents/Workspace/foodplaza-fastApi/.venv/lib/python3.12/site-packages/uvicorn/middleware/proxy_headers.py", line 84, in __call__
    return await self.app(scope, receive, send)
           ^^^^^^^^^^^^^^^^^^^^^^^^^^^^^^^^^^^^
  File "/home/poncho/Documents/Workspace/foodplaza-fastApi/.venv/lib/python3.12/site-packages/fastapi/applications.py", line 1054, in __call__
    await super().__call__(scope, receive, send)
  File "/home/poncho/Documents/Workspace/foodplaza-fastApi/.venv/lib/python3.12/site-packages/starlette/applications.py", line 123, in __call__
    await self.middleware_stack(scope, receive, send)
  File "/home/poncho/Documents/Workspace/foodplaza-fastApi/.venv/lib/python3.12/site-packages/starlette/middleware/errors.py", line 186, in __call__
    raise exc
  File "/home/poncho/Documents/Workspace/foodplaza-fastApi/.venv/lib/python3.12/site-packages/starlette/middleware/errors.py", line 164, in __call__
    await self.app(scope, receive, _send)
  File "/home/poncho/Documents/Workspace/foodplaza-fastApi/.venv/lib/python3.12/site-packages/starlette/middleware/cors.py", line 83, in __call__
    await self.app(scope, receive, send)
  File "/home/poncho/Documents/Workspace/foodplaza-fastApi/.venv/lib/python3.12/site-packages/starlette/middleware/exceptions.py", line 62, in __call__
    await wrap_app_handling_exceptions(self.app, conn)(scope, receive, send)
  File "/home/poncho/Documents/Workspace/foodplaza-fastApi/.venv/lib/python3.12/site-packages/starlette/_exception_handler.py", line 64, in wrapped_app
    raise exc
  File "/home/poncho/Documents/Workspace/foodplaza-fastApi/.venv/lib/python3.12/site-packages/starlette/_exception_handler.py", line 53, in wrapped_app
    await app(scope, receive, sender)
  File "/home/poncho/Documents/Workspace/foodplaza-fastApi/.venv/lib/python3.12/site-packages/starlette/routing.py", line 758, in __call__
    await self.middleware_stack(scope, receive, send)
  File "/home/poncho/Documents/Workspace/foodplaza-fastApi/.venv/lib/python3.12/site-packages/starlette/routing.py", line 778, in app
    await route.handle(scope, receive, send)
  File "/home/poncho/Documents/Workspace/foodplaza-fastApi/.venv/lib/python3.12/site-packages/starlette/routing.py", line 299, in handle
    await self.app(scope, receive, send)
  File "/home/poncho/Documents/Workspace/foodplaza-fastApi/.venv/lib/python3.12/site-packages/starlette/routing.py", line 79, in app
    await wrap_app_handling_exceptions(app, request)(scope, receive, send)
  File "/home/poncho/Documents/Workspace/foodplaza-fastApi/.venv/lib/python3.12/site-packages/starlette/_exception_handler.py", line 64, in wrapped_app
    raise exc
  File "/home/poncho/Documents/Workspace/foodplaza-fastApi/.venv/lib/python3.12/site-packages/starlette/_exception_handler.py", line 53, in wrapped_app
    await app(scope, receive, sender)
  File "/home/poncho/Documents/Workspace/foodplaza-fastApi/.venv/lib/python3.12/site-packages/starlette/routing.py", line 74, in app
    response = await func(request)
               ^^^^^^^^^^^^^^^^^^^
  File "/home/poncho/Documents/Workspace/foodplaza-fastApi/.venv/lib/python3.12/site-packages/fastapi/routing.py", line 299, in app
    raise e
  File "/home/poncho/Documents/Workspace/foodplaza-fastApi/.venv/lib/python3.12/site-packages/fastapi/routing.py", line 294, in app
    raw_response = await run_endpoint_function(
                   ^^^^^^^^^^^^^^^^^^^^^^^^^^^^
  File "/home/poncho/Documents/Workspace/foodplaza-fastApi/.venv/lib/python3.12/site-packages/fastapi/routing.py", line 193, in run_endpoint_function
    return await run_in_threadpool(dependant.call, **values)
           ^^^^^^^^^^^^^^^^^^^^^^^^^^^^^^^^^^^^^^^^^^^^^^^^^
  File "/home/poncho/Documents/Workspace/foodplaza-fastApi/.venv/lib/python3.12/site-packages/starlette/concurrency.py", line 42, in run_in_threadpool
    return await anyio.to_thread.run_sync(func, *args)
           ^^^^^^^^^^^^^^^^^^^^^^^^^^^^^^^^^^^^^^^^^^^
  File "/home/poncho/Documents/Workspace/foodplaza-fastApi/.venv/lib/python3.12/site-packages/anyio/to_thread.py", line 33, in run_sync
    return await get_asynclib().run_sync_in_worker_thread(
           ^^^^^^^^^^^^^^^^^^^^^^^^^^^^^^^^^^^^^^^^^^^^^^^
  File "/home/poncho/Documents/Workspace/foodplaza-fastApi/.venv/lib/python3.12/site-packages/anyio/_backends/_asyncio.py", line 877, in run_sync_in_worker_thread
    return await future
           ^^^^^^^^^^^^
  File "/home/poncho/Documents/Workspace/foodplaza-fastApi/.venv/lib/python3.12/site-packages/anyio/_backends/_asyncio.py", line 807, in run
    result = context.run(func, *args)
             ^^^^^^^^^^^^^^^^^^^^^^^^
  File "/home/poncho/Documents/Workspace/foodplaza-fastApi/app/routers/pedidos.py", line 207, in obtener_pedidos_local
    db_local = db.query(LocaleDB).filter(LocaleDB.id == local_id).first()
               ^^^^^^^^^^^^^^^^^^^^^^^^^^^^^^^^^^^^^^^^^^^^^^^^^^^^^^^^^^
  File "/home/poncho/Documents/Workspace/foodplaza-fastApi/.venv/lib/python3.12/site-packages/sqlalchemy/orm/query.py", line 2748, in first
    return self.limit(1)._iter().first()  # type: ignore
           ^^^^^^^^^^^^^^^^^^^^^
  File "/home/poncho/Documents/Workspace/foodplaza-fastApi/.venv/lib/python3.12/site-packages/sqlalchemy/orm/query.py", line 2847, in _iter
    result: Union[ScalarResult[_T], Result[_T]] = self.session.execute(
                                                  ^^^^^^^^^^^^^^^^^^^^^
  File "/home/poncho/Documents/Workspace/foodplaza-fastApi/.venv/lib/python3.12/site-packages/sqlalchemy/orm/session.py", line 2308, in execute
    return self._execute_internal(
           ^^^^^^^^^^^^^^^^^^^^^^^
  File "/home/poncho/Documents/Workspace/foodplaza-fastApi/.venv/lib/python3.12/site-packages/sqlalchemy/orm/session.py", line 2180, in _execute_internal
    conn = self._connection_for_bind(bind)
           ^^^^^^^^^^^^^^^^^^^^^^^^^^^^^^^
  File "/home/poncho/Documents/Workspace/foodplaza-fastApi/.venv/lib/python3.12/site-packages/sqlalchemy/orm/session.py", line 2047, in _connection_for_bind
    return trans._connection_for_bind(engine, execution_options)
           ^^^^^^^^^^^^^^^^^^^^^^^^^^^^^^^^^^^^^^^^^^^^^^^^^^^^^
  File "<string>", line 2, in _connection_for_bind
  File "/home/poncho/Documents/Workspace/foodplaza-fastApi/.venv/lib/python3.12/site-packages/sqlalchemy/orm/state_changes.py", line 139, in _go
    ret_value = fn(self, *arg, **kw)
                ^^^^^^^^^^^^^^^^^^^^
  File "/home/poncho/Documents/Workspace/foodplaza-fastApi/.venv/lib/python3.12/site-packages/sqlalchemy/orm/session.py", line 1143, in _connection_for_bind
    conn = bind.connect()
           ^^^^^^^^^^^^^^
  File "/home/poncho/Documents/Workspace/foodplaza-fastApi/.venv/lib/python3.12/site-packages/sqlalchemy/engine/base.py", line 3268, in connect
    return self._connection_cls(self)
           ^^^^^^^^^^^^^^^^^^^^^^^^^^
  File "/home/poncho/Documents/Workspace/foodplaza-fastApi/.venv/lib/python3.12/site-packages/sqlalchemy/engine/base.py", line 147, in __init__
    Connection._handle_dbapi_exception_noconnection(
  File "/home/poncho/Documents/Workspace/foodplaza-fastApi/.venv/lib/python3.12/site-packages/sqlalchemy/engine/base.py", line 2430, in _handle_dbapi_exception_noconnection
    raise sqlalchemy_exception.with_traceback(exc_info[2]) from e
  File "/home/poncho/Documents/Workspace/foodplaza-fastApi/.venv/lib/python3.12/site-packages/sqlalchemy/engine/base.py", line 145, in __init__
    self._dbapi_connection = engine.raw_connection()
                             ^^^^^^^^^^^^^^^^^^^^^^^
  File "/home/poncho/Documents/Workspace/foodplaza-fastApi/.venv/lib/python3.12/site-packages/sqlalchemy/engine/base.py", line 3292, in raw_connection
    return self.pool.connect()
           ^^^^^^^^^^^^^^^^^^^
  File "/home/poncho/Documents/Workspace/foodplaza-fastApi/.venv/lib/python3.12/site-packages/sqlalchemy/pool/base.py", line 452, in connect
    return _ConnectionFairy._checkout(self)
           ^^^^^^^^^^^^^^^^^^^^^^^^^^^^^^^^
  File "/home/poncho/Documents/Workspace/foodplaza-fastApi/.venv/lib/python3.12/site-packages/sqlalchemy/pool/base.py", line 1269, in _checkout
    fairy = _ConnectionRecord.checkout(pool)
            ^^^^^^^^^^^^^^^^^^^^^^^^^^^^^^^^
  File "/home/poncho/Documents/Workspace/foodplaza-fastApi/.venv/lib/python3.12/site-packages/sqlalchemy/pool/base.py", line 716, in checkout
    rec = pool._do_get()
          ^^^^^^^^^^^^^^
  File "/home/poncho/Documents/Workspace/foodplaza-fastApi/.venv/lib/python3.12/site-packages/sqlalchemy/pool/impl.py", line 169, in _do_get
    with util.safe_reraise():
  File "/home/poncho/Documents/Workspace/foodplaza-fastApi/.venv/lib/python3.12/site-packages/sqlalchemy/util/langhelpers.py", line 146, in __exit__
    raise exc_value.with_traceback(exc_tb)
  File "/home/poncho/Documents/Workspace/foodplaza-fastApi/.venv/lib/python3.12/site-packages/sqlalchemy/pool/impl.py", line 167, in _do_get
    return self._create_connection()
           ^^^^^^^^^^^^^^^^^^^^^^^^^
  File "/home/poncho/Documents/Workspace/foodplaza-fastApi/.venv/lib/python3.12/site-packages/sqlalchemy/pool/base.py", line 393, in _create_connection
    return _ConnectionRecord(self)
           ^^^^^^^^^^^^^^^^^^^^^^^
  File "/home/poncho/Documents/Workspace/foodplaza-fastApi/.venv/lib/python3.12/site-packages/sqlalchemy/pool/base.py", line 678, in __init__
    self.__connect()
  File "/home/poncho/Documents/Workspace/foodplaza-fastApi/.venv/lib/python3.12/site-packages/sqlalchemy/pool/base.py", line 902, in __connect
    with util.safe_reraise():
  File "/home/poncho/Documents/Workspace/foodplaza-fastApi/.venv/lib/python3.12/site-packages/sqlalchemy/util/langhelpers.py", line 146, in __exit__
    raise exc_value.with_traceback(exc_tb)
  File "/home/poncho/Documents/Workspace/foodplaza-fastApi/.venv/lib/python3.12/site-packages/sqlalchemy/pool/base.py", line 898, in __connect
    self.dbapi_connection = connection = pool._invoke_creator(self)
                                         ^^^^^^^^^^^^^^^^^^^^^^^^^^
  File "/home/poncho/Documents/Workspace/foodplaza-fastApi/.venv/lib/python3.12/site-packages/sqlalchemy/engine/create.py", line 637, in connect
    return dialect.connect(*cargs, **cparams)
           ^^^^^^^^^^^^^^^^^^^^^^^^^^^^^^^^^^
  File "/home/poncho/Documents/Workspace/foodplaza-fastApi/.venv/lib/python3.12/site-packages/sqlalchemy/engine/default.py", line 616, in connect
    return self.loaded_dbapi.connect(*cargs, **cparams)
           ^^^^^^^^^^^^^^^^^^^^^^^^^^^^^^^^^^^^^^^^^^^^
  File "/home/poncho/Documents/Workspace/foodplaza-fastApi/.venv/lib/python3.12/site-packages/pymysql/connections.py", line 358, in __init__
    self.connect()
  File "/home/poncho/Documents/Workspace/foodplaza-fastApi/.venv/lib/python3.12/site-packages/pymysql/connections.py", line 664, in connect
    self._request_authentication()
  File "/home/poncho/Documents/Workspace/foodplaza-fastApi/.venv/lib/python3.12/site-packages/pymysql/connections.py", line 976, in _request_authentication
    auth_packet = _auth.caching_sha2_password_auth(self, auth_packet)
                  ^^^^^^^^^^^^^^^^^^^^^^^^^^^^^^^^^^^^^^^^^^^^^^^^^^^
  File "/home/poncho/Documents/Workspace/foodplaza-fastApi/.venv/lib/python3.12/site-packages/pymysql/_auth.py", line 267, in caching_sha2_password_auth
    pkt = _roundtrip(conn, data)
          ^^^^^^^^^^^^^^^^^^^^^^
  File "/home/poncho/Documents/Workspace/foodplaza-fastApi/.venv/lib/python3.12/site-packages/pymysql/_auth.py", line 120, in _roundtrip
    pkt = conn._read_packet()
          ^^^^^^^^^^^^^^^^^^^
  File "/home/poncho/Documents/Workspace/foodplaza-fastApi/.venv/lib/python3.12/site-packages/pymysql/connections.py", line 772, in _read_packet
    packet.raise_for_error()
  File "/home/poncho/Documents/Workspace/foodplaza-fastApi/.venv/lib/python3.12/site-packages/pymysql/protocol.py", line 221, in raise_for_error
    err.raise_mysql_exception(self._data)
  File "/home/poncho/Documents/Workspace/foodplaza-fastApi/.venv/lib/python3.12/site-packages/pymysql/err.py", line 143, in raise_mysql_exception
    raise errorclass(errno, errval)
sqlalchemy.exc.OperationalError: (pymysql.err.OperationalError) (1045, "Access denied for user 'root'@'localhost' (using password: YES)")
(Background on this error at: https://sqlalche.me/e/20/e3q8)
